Workbook

Sheet Actor
A5: Age | B5: 44.370427
B6: 13.179851
B7: 102
A8: Less than 50 employees | B8: 0.59375
B9: 0.49371044
B10: 96
A11: Percentage paid to lawyer | B11: 28.298246
B12: 11.112999
B13: 57
A14: Expected probability winning the trial by the other party | B14: 48.676471
B15: 34.056785
B16: 102
A17: More than secondary education | B17: 0.42156863
B18: 0.49624879
B19: 102
A20: Has changed lawyer during trial | B20: 0.088235294
B21: 0.28503747
B22: 102
A23: Expected probability of winning trial | B23: 79
B24: 21.299375
B25: 102
A26: Median expected recovery amount (Pesos) | B26: 21000
B27: NA
B28: 102
A29: Expected duration (years) | B29: 3.6446078
B30: 9.7569326
B31: 102
A32: Was treated poorly/very poorly by former employer | B32: 0.54901961
B33: NA
B34: 102
A35: The company mistreats its employees
B36: 0.7745098
B37: 0.41996847
B38: 102
A39: Is very angry with company | B39: 0.46078431
B40: 0.5009213
B41: 102
A42: Repeated player | B42: 0.17647059
B43: 0.38310262
B44: 102
...

Sheet Lawyers
A5: Age | B5: 37.785412 | C5: 36.5584
B6: 12.433876 | C6: 10.971427
B7: 231 | C7: 223
A8: Tenure | B8: 9.2541436 | C8: 18.65285
B9: 8.8807874 | C9: 143.32444
B10: 181 | C10: 193
A11: More than 100 historical cases | B11: 0.49350649 | C11: 0.60538117
B12: 0.50104352 | C12: 0.48986826
B13: 231 | C13: 223
A14: More than 30 current lawsuits | B14: 0.5974026 | C14: 0.67713004
B15: 0.49148595 | C15: 0.46862538
B16: 231 | C16: 223
A17: Less than 50 employees | B17: 0.65317919 | C17: 0.45695364
B18: 0.47733972 | C18: 0.49980129
B19: 173 | C19: 151
A20: Percentage paid to lawyer | B20: 29.686047
B21: 7.7870212
B22: 172
A23: Expected probability winning the trial by the other party | B23: 52.008658 | C23: 54.950673
B24: 24.666822 | C24: 27.963978
B25: 231 | C25: 223
A26: Expected probability of winning trial | B26: 72.194805 | C26: 70.479821
B27: 20.140834 | C27: 21.528282
B28: 231 | C28: 223
A29: Median expected recovery amount (Pesos) | B29: 35000 | C29: 11000
B30: NA | C30: NA
B31: 231 | C31: 223
A32: Expected duration (years) | B32: 3.9415584 | C32: 4.1748879
B33: 2.3023984 | C33: 2.5440798
B34: 231 | C34: 223

Sheet surveySS
B3: Panel A: worker characteristics
D4: Mean | G4: Mean
D5: (SD) | G5: (SD)
D6: N | G6: N
B7: =Actor!A5 -> Age | D7: =ROUND(Actor!B5,2) -> 44.37 | E7: =Actor!A20 -> Has changed lawyer during trial | G7: =ROUND(Actor!B20,2) -> 0.09
D8: =_xlfn.CONCAT("(",ROUND(Actor!B6,2),")") -> (13.18) | G8: =_xlfn.CONCAT("(",ROUND(Actor!B21,2),")") -> (0.29)
D9: =ROUND(Actor!B7,2) -> 102 | G9: =Actor!B22 -> 102
B10: =Actor!A8 -> Less than 50 employees | D10: =ROUND(Actor!B8,2) -> 0.59 | E10: =Actor!A23 -> Expected probability of winning trial | G10: =Actor!B23 -> 79
D11: =_xlfn.CONCAT("(",ROUND(Actor!B9,2),")") -> (0.49) | G11: =_xlfn.CONCAT("(",ROUND(Actor!B24,2),")") -> (21.3)
D12: =ROUND(Actor!B10,2) -> 96 | G12: =Actor!B25 -> 102
B13: =Actor!A11 -> Percentage paid to lawyer | D13: =ROUND(Actor!B11,2) -> 28.3 | E13: =Actor!A26 -> Median expected recovery amount (Pesos) | G13: =ROUND(Actor!B26,2) -> 21000
D14: =_xlfn.CONCAT("(",ROUND(Actor!B12,2),")") -> (11.11) | G14: =Actor!B27 -> NA
D15: =Actor!B13 -> 57 | G15: =Actor!B28 -> 102
B16: =Actor!A14 -> Expected probability winning the trial by the other party | D16: =ROUND(Actor!B14,2) -> 48.68 | E16: =Actor!A29 -> Expected duration (years) | G16: =ROUND(Actor!B29,2) -> 3.64
D17: =_xlfn.CONCAT("(",ROUND(Actor!B15,2),")") -> (34.06) | G17: =_xlfn.CONCAT("(",ROUND(Actor!B30,2),")") -> (9.76)
D18: =Actor!B16 -> 102 | G18: =Actor!B31 -> 102
B19: =Actor!A17 -> More than secondary education | D19: =ROUND(Actor!B17,2) -> 0.42 | E19: =Actor!A32 -> Was treated poorly/very poorly by former employer | G19: =ROUND(Actor!B32,2) -> 0.55
D20: =_xlfn.CONCAT("(",ROUND(Actor!B18,2),")") -> (0.5) | G20: =Actor!B33 -> NA
D21: =Actor!B19 -> 102 | G21: =Actor!B34 -> 102
B23: Panel B: lawyer characteristics
D24: Worker's lawyer | F24: Employer's lawyer
D25: Mean | F25: Mean
D26: (SD) | F26: (SD)
D27: N | F27: N
B28: =Lawyers!A5 -> Age | D28: =ROUND(Lawyers!B5,2) -> 37.79 | F28: =ROUND(Lawyers!C5,2) -> 36.56
D29: =_xlfn.CONCAT("(",ROUND(Lawyers!B6,2),")") -> (12.43) | F29: =_xlfn.CONCAT("(",ROUND(Lawyers!C6,2),")") -> (10.97)
D30: =ROUND(Lawyers!B7,2) -> 231 | F30: =ROUND(Lawyers!C7,2) -> 223
B31: =Lawyers!A8 -> Tenure | D31: =ROUND(Lawyers!B8,2) -> 9.25 | F31: =ROUND(Lawyers!C8,2) -> 18.65
D32: =_xlfn.CONCAT("(",ROUND(Lawyers!B9,2),")") -> (8.88) | F32: =_xlfn.CONCAT("(",ROUND(Lawyers!C9,2),")") -> (143.32)
D33: =ROUND(Lawyers!B10,2) -> 181 | F33: =ROUND(Lawyers!C10,2) -> 193
B34: =Lawyers!A11 -> More than 100 historical cases | D34: =ROUND(Lawyers!B11,2) -> 0.49 | F34: =ROUND(Lawyers!C11,2) -> 0.61
D35: =_xlfn.CONCAT("(",ROUND(Lawyers!B12,2),")") -> (0.5) | F35: =_xlfn.CONCAT("(",ROUND(Lawyers!C12,2),")") -> (0.49)
D36: =ROUND(Lawyers!B13,2) -> 231 | F36: =ROUND(Lawyers!C13,2) -> 223
B37: =Lawyers!A14 -> More than 30 current lawsuits | D37: =ROUND(Lawyers!B14,2) -> 0.6 | F37: =ROUND(Lawyers!C14,2) -> 0.68
D38: =_xlfn.CONCAT("(",ROUND(Lawyers!B15,2),")") -> (0.49) | F38: =_xlfn.CONCAT("(",ROUND(Lawyers!C15,2),")") -> (0.47)
D39: =Lawyers!B16 -> 231 | F39: =Lawyers!C16 -> 223
B40: =Lawyers!A17 -> Less than 50 employees | D40: =ROUND(Lawyers!B17,2) -> 0.65 | F40: =ROUND(Lawyers!C17,2) -> 0.46
D41: =_xlfn.CONCAT("(",ROUND(Lawyers!B18,2),")") -> (0.48) | F41: =_xlfn.CONCAT("(",ROUND(Lawyers!C18,2),")") -> (0.5)
D42: =Lawyers!B19 -> 173 | F42: =Lawyers!C19 -> 151
B43: =Lawyers!A20 -> Percentage paid to lawyer | D43: =ROUND(Lawyers!B20,2) -> 29.69
...
